Workbook

Sheet 注文書
B1: 選択しない | C1: 記入日 | D1: =TODAY() -> 46212
A2: 注 文 書 | D2: （保育園控え）
B3: 株式会社若林商店 殿
A4: 下記のとおり注文します。
C5: （施設名）
A6: 〇/〇記入可 順不同可能 | B6: リストにないものも自由記入可 | C6: kg記入統一 | D6: 特殊カットのみ選択 自由記入可能
A7: 納入指定 月 日 | B7: 品 名 | C7: 単位呼称 | D7: 数 量 | E7: レ
D24: 園長印

Sheet 業者発注票
B1: =IF(注文書!B1="","",注文書!B1) -> 選択しない | C1: 記入日 | D1: =IF(注文書!D1="","",注文書!D1) -> 46212
A2: 注 文 書 | D2: （業者発注票）
A3: 株式会社若林商店 殿 | C3: =IF(注文書!C3="","",注文書!C3)
A4: 下記のとおり注文します。
A5: 〇/〇記入可 順不同可能 | B5: リストにないものも自由記入可 | C5: kg記入統一 | D5: 特殊カットのみ選択 自由記入可能
A6: 納入指定 月 日 | B6: 品 名 | C6: 数 量 | D6: 備 考
A7: =IF(注文書!A8="","",注文書!A8) | B7: =IF(注文書!B8="","",注文書!B8) | C7: =IF(注文書!D8="","",注文書!D8) | D7: =IF(注文書!C8="","",注文書!C8)
A8: =IF(注文書!A9="","",注文書!A9) | B8: =IF(注文書!B9="","",注文書!B9) | C8: =IF(注文書!D9="","",注文書!D9) | D8: =IF(注文書!C9="","",注文書!C9)
A9: =IF(注文書!A10="","",注文書!A10) | B9: =IF(注文書!B10="","",注文書!B10) | C9: =IF(注文書!D10="","",注文書!D10) | D9: =IF(注文書!C10="","",注文書!C10)
A10: =IF(注文書!A11="","",注文書!A11) | B10: =IF(注文書!B11="","",注文書!B11) | C10: =IF(注文書!D11="","",注文書!D11) | D10: =IF(注文書!C11="","",注文書!C11)
A11: =IF(注文書!A12="","",注文書!A12) | B11: =IF(注文書!B12="","",注文書!B12) | C11: =IF(注文書!D12="","",注文書!D12) | D11: =IF(注文書!C12="","",注文書!C12)
A12: =IF(注文書!A13="","",注文書!A13) | B12: =IF(注文書!B13="","",注文書!B13) | C12: =IF(注文書!D13="","",注文書!D13) | D12: =IF(注文書!C13="","",注文書!C13)
A13: =IF(注文書!A14="","",注文書!A14) | B13: =IF(注文書!B14="","",注文書!B14) | C13: =IF(注文書!D14="","",注文書!D14) | D13: =IF(注文書!C14="","",注文書!C14)
A14: =IF(注文書!A15="","",注文書!A15) | B14: =IF(注文書!B15="","",注文書!B15) | C14: =IF(注文書!D15="","",注文書!D15) | D14: =IF(注文書!C15="","",注文書!C15)
A15: =IF(注文書!A16="","",注文書!A16) | B15: =IF(注文書!B16="","",注文書!B16) | C15: =IF(注文書!D16="","",注文書!D16) | D15: =IF(注文書!C16="","",注文書!C16)
A16: =IF(注文書!A17="","",注文書!A17) | B16: =IF(注文書!B17="","",注文書!B17) | C16: =IF(注文書!D17="","",注文書!D17) | D16: =IF(注文書!C17="","",注文書!C17)
A17: =IF(注文書!A18="","",注文書!A18) | B17: =IF(注文書!B18="","",注文書!B18) | C17: =IF(注文書!D18="","",注文書!D18) | D17: =IF(注文書!C18="","",注文書!C18)
A18: =IF(注文書!A19="","",注文書!A19) | B18: =IF(注文書!B19="","",注文書!B19) | C18: =IF(注文書!D19="","",注文書!D19) | D18: =IF(注文書!C19="","",注文書!C19)
... A22: =IF(注文書!A23="","",注文書!A23) | B22: =IF(注文書!B23="","",注文書!B23) | C22: =IF(注文書!D23="","",注文書!D23) | D22: =IF(注文書!C23="","",注文書!C23)
D23: 園長印

Sheet 注文書 (2)
B1: 選択しない | C1: 記入日 | D1: =TODAY() -> 46212
A2: 注 文 書 | D2: （保育園控え）
B3: 株式会社若林商店 殿
A4: 下記のとおり注文します。
C5: （施設名）
A6: 〇/〇記入可 順不同可能 | B6: リストにないものも自由記入可 | C6: kg記入統一 | D6: 特殊カットのみ選択 自由記入可能
A7: 納入指定 月 日 | B7: 品 名 | C7: 単位呼称 | D7: 数 量 | E7: レ
D24: 園長印

Sheet 商品名一覧
A1: 商品名一覧（灰色枠内編集OKです） | B1: 説明
A2: 【豚肉】
A3: 豚こま
A4: 豚こま（脂なし）
A5: 豚ももこま
A6: 豚ももこま（脂なし）
A7: 豚ひき
A8: 豚ひき（脂なし）
A9: 豚ももひき
A10: 豚ももひき（脂なし）
A11: 豚バラ
A12: 豚カタロース
A13: 豚ロース
... A33: 鶏手羽元
A34: 鶏手羽元（切り込み） | B34: 繁忙期の切込みは受注不可の場合があります
A35: 鶏手羽先
A36: 鶏手羽先（切り込み） | B36: 繁忙期の切込みは受注不可の場合があります
A37: 鶏骨付きモモ
A38: 鶏骨付きモモ（切り込み） | B38: 繁忙期の切込みは受注不可の場合があります
A39: 鶏レバー
A40: 鶏ガラパック
A41: 【ハム類】
A42: ロースハム
A43: ポークハム
A44: ベーコン
A45: ウインナー
A46: フランクフルト
A47: ソフトサラミ
A48: 【牛肉】
A49: 牛スライス
A50: 牛こま（脂なし）
... A53: 合いびき

Sheet 備考一覧
A1: 備考一覧 | B1: 説明
A2: 極小こま
A3: 短冊切り
A4: 千切り
A5: 角切り
A6: 色紙切り
A7: g* | B7: 30g*45 このような簡易表記でOKです ＝30g×45枚 | D7: *=×の意味です
A8: g* 開き
A9: g×
A10: g× 開き
A11: 本 | B11: ササミなどの本数発注は重量未記入でOKです
A12: 枚

Sheet 使い方
A1: いつもお世話になっています。
A2: 発注書ひな形です、ご自由に編集してお使いください。
A3: ご不明点はお気軽にお問い合わせください。
A5: こま肉の大きさに関しましては基本的には当社規定の保育園様向けの小さめサイズで納品しています。
A6: 特殊な切り方指定がある場合のみ備考欄にて指定をお願いいたします。
A8: g指定切りは備考欄に〇ｇ*△枚数と記入。可能であれば合計重量の記入も願います。未記入の場合枚数に合わせて合計重量計算いたします。
A9: *と×は同じ意味です、お好きな表記で構いません。g指定切りに関してはドロップダウンリストを使用せず直接キーボードでの入力が簡単です。
A11: 商品名一覧と備考欄一覧の灰色背景枠内でご自由に表記登録が可能です、宛名を変更していただければ他社様宛の発注書にも転用可能です。
A13: 株式会社若林商店 FAX：03-3637-8501

Sheet 日付リスト
A2: =IF(ISNUMBER(注文書!$B$1),IF(MONTH(注文書!$B$1+0)=MONTH(注文書!$B$1),注文書!$B$1+0,""),TODAY()+0) -> 46212 | C2: 選択しない
A3: =IF(ISNUMBER(注文書!$B$1),IF(MONTH(注文書!$B$1+1)=MONTH(注文書!$B$1),注文書!$B$1+1,""),TODAY()+1) -> 46213 | C3: 46174
A4: =IF(ISNUMBER(注文書!$B$1),IF(MONTH(注文書!$B$1+2)=MONTH(注文書!$B$1),注文書!$B$1+2,""),TODAY()+2) -> 46214 | C4: 46204
A5: =IF(ISNUMBER(注文書!$B$1),IF(MONTH(注文書!$B$1+3)=MONTH(注文書!$B$1),注文書!$B$1+3,""),TODAY()+3) -> 46215 | C5: 46235
A6: =IF(ISNUMBER(注文書!$B$1),IF(MONTH(注文書!$B$1+4)=MONTH(注文書!$B$1),注文書!$B$1+4,""),TODAY()+4) -> 46216 | C6: 46266
A7: =IF(ISNUMBER(注文書!$B$1),IF(MONTH(注文書!$B$1+5)=MONTH(注文書!$B$1),注文書!$B$1+5,""),TODAY()+5) -> 46217 | C7: 46296
A8: =IF(ISNUMBER(注文書!$B$1),IF(MONTH(注文書!$B$1+6)=MONTH(注文書!$B$1),注文書!$B$1+6,""),TODAY()+6) -> 46218 | C8: 46327
A9: =IF(ISNUMBER(注文書!$B$1),IF(MONTH(注文書!$B$1+7)=MONTH(注文書!$B$1),注文書!$B$1+7,""),TODAY()+7) -> 46219 | C9: 46357
A10: =IF(ISNUMBER(注文書!$B$1),IF(MONTH(注文書!$B$1+8)=MONTH(注文書!$B$1),注文書!$B$1+8,""),TODAY()+8) -> 46220 | C10: 46388
A11: =IF(ISNUMBER(注文書!$B$1),IF(MONTH(注文書!$B$1+9)=MONTH(注文書!$B$1),注文書!$B$1+9,""),TODAY()+9) -> 46221 | C11: 46419
A12: =IF(ISNUMBER(注文書!$B$1),IF(MONTH(注文書!$B$1+10)=MONTH(注文書!$B$1),注文書!$B$1+10,""),TODAY()+10) -> 46222 | C12: 46447
A13: =IF(ISNUMBER(注文書!$B$1),IF(MONTH(注文書!$B$1+11)=MONTH(注文書!$B$1),注文書!$B$1+11,""),TODAY()+11) -> 46223 | C13: 46478
A14: =IF(ISNUMBER(注文書!$B$1),IF(MONTH(注文書!$B$1+12)=MONTH(注文書!$B$1),注文書!$B$1+12,""),TODAY()+12) -> 46224 | C14: 46508
A15: =IF(ISNUMBER(注文書!$B$1),IF(MONTH(注文書!$B$1+13)=MONTH(注文書!$B$1),注文書!$B$1+13,""),TODAY()+13) -> 46225
A16: =IF(ISNUMBER(注文書!$B$1),IF(MONTH(注文書!$B$1+14)=MONTH(注文書!$B$1),注文書!$B$1+14,""),TODAY()+14) -> 46226
A17: =IF(ISNUMBER(注文書!$B$1),IF(MONTH(注文書!$B$1+15)=MONTH(注文書!$B$1),注文書!$B$1+15,""),TODAY()+15) -> 46227
A18: =IF(ISNUMBER(注文書!$B$1),IF(MONTH(注文書!$B$1+16)=MONTH(注文書!$B$1),注文書!$B$1+16,""),TODAY()+16) -> 46228
A19: =IF(ISNUMBER(注文書!$B$1),IF(MONTH(注文書!$B$1+17)=MONTH(注文書!$B$1),注文書!$B$1+17,""),TODAY()+17) -> 46229
A20: =IF(ISNUMBER(注文書!$B$1),IF(MONTH(注文書!$B$1+18)=MONTH(注文書!$B$1),注文書!$B$1+18,""),TODAY()+18) -> 46230
A21: =IF(ISNUMBER(注文書!$B$1),IF(MONTH(注文書!$B$1+19)=MONTH(注文書!$B$1),注文書!$B$1+19,""),TODAY()+19) -> 46231
A22: =IF(ISNUMBER(注文書!$B$1),IF(MONTH(注文書!$B$1+20)=MONTH(注文書!$B$1),注文書!$B$1+20,""),TODAY()+20) -> 46232
A23: =IF(ISNUMBER(注文書!$B$1),IF(MONTH(注文書!$B$1+21)=MONTH(注文書!$B$1),注文書!$B$1+21,""),TODAY()+21) -> 46233
A24: =IF(ISNUMBER(注文書!$B$1),IF(MONTH(注文書!$B$1+22)=MONTH(注文書!$B$1),注文書!$B$1+22,""),TODAY()+22) -> 46234
A25: =IF(ISNUMBER(注文書!$B$1),IF(MONTH(注文書!$B$1+23)=MONTH(注文書!$B$1),注文書!$B$1+23,""),TODAY()+23) -> 46235
A26: =IF(ISNUMBER(注文書!$B$1),IF(MONTH(注文書!$B$1+24)=MONTH(注文書!$B$1),注文書!$B$1+24,""),TODAY()+24) -> 46236
A27: =IF(ISNUMBER(注文書!$B$1),IF(MONTH(注文書!$B$1+25)=MONTH(注文書!$B$1),注文書!$B$1+25,""),TODAY()+25) -> 46237
A28: =IF(ISNUMBER(注文書!$B$1),IF(MONTH(注文書!$B$1+26)=MONTH(注文書!$B$1),注文書!$B$1+26,""),TODAY()+26) -> 46238
A29: =IF(ISNUMBER(注文書!$B$1),IF(MONTH(注文書!$B$1+27)=MONTH(注文書!$B$1),注文書!$B$1+27,""),TODAY()+27) -> 46239
A30: =IF(ISNUMBER(注文書!$B$1),IF(MONTH(注文書!$B$1+28)=MONTH(注文書!$B$1),注文書!$B$1+28,""),TODAY()+28) -> 46240
A31: =IF(ISNUMBER(注文書!$B$1),IF(MONTH(注文書!$B$1+29)=MONTH(注文書!$B$1),注文書!$B$1+29,""),TODAY()+29) -> 46241
A32: =IF(ISNUMBER(注文書!$B$1),IF(MONTH(注文書!$B$1+30)=MONTH(注文書!$B$1),注文書!$B$1+30,""),TODAY()+30) -> 46242
A33: =IF(ISNUMBER(注文書!$B$1),IF(MONTH(注文書!$B$1+31)=MONTH(注文書!$B$1),注文書!$B$1+31,""),TODAY()+31) -> 46243
A34: =IF(ISNUMBER(注文書!$B$1),IF(MONTH(注文書!$B$1+32)=MONTH(注文書!$B$1),注文書!$B$1+32,""),TODAY()+32) -> 46244
A35: =IF(ISNUMBER(注文書!$B$1),IF(MONTH(注文書!$B$1+33)=MONTH(注文書!$B$1),注文書!$B$1+33,""),TODAY()+33) -> 46245
A36: =IF(ISNUMBER(注文書!$B$1),IF(MONTH(注文書!$B$1+34)=MONTH(注文書!$B$1),注文書!$B$1+34,""),TODAY()+34) -> 46246
A37: =IF(ISNUMBER(注文書!$B$1),IF(MONTH(注文書!$B$1+35)=MONTH(注文書!$B$1),注文書!$B$1+35,""),TODAY()+35) -> 46247
A38: =IF(ISNUMBER(注文書!$B$1),IF(MONTH(注文書!$B$1+36)=MONTH(注文書!$B$1),注文書!$B$1+36,""),TODAY()+36) -> 46248
A39: =IF(ISNUMBER(注文書!$B$1),IF(MONTH(注文書!$B$1+37)=MONTH(注文書!$B$1),注文書!$B$1+37,""),TODAY()+37) -> 46249
A40: =IF(ISNUMBER(注文書!$B$1),IF(MONTH(注文書!$B$1+38)=MONTH(注文書!$B$1),注文書!$B$1+38,""),TODAY()+38) -> 46250
A41: =IF(ISNUMBER(注文書!$B$1),IF(MONTH(注文書!$B$1+39)=MONTH(注文書!$B$1),注文書!$B$1+39,""),TODAY()+39) -> 46251
...
