Workbook

Sheet 注文書
B1: 必要であれば年月を選択 | C1: 記入日 | D1: =TODAY() -> 46311
A2: 注 文 書
A3: 株式会社若林商店宛 FAX03-3637-8501 | C3: 施設名記入
A5: 〇/〇記入可 順不同可能 | B5: リストにないものも自由記入可 | C5: kg記入統一 | D5: 特殊カットのみ選択 自由記入可能
A6: 納品日 月 日 | B6: 品 名 | C6: 数 量 | D6: 備 考

Sheet 商品名一覧
A1: 商品名一覧（灰色枠内編集OKです） | B1: 説明
A2: 【豚肉】
A3: 豚こま
A4: 豚こま(脂なし)
A5: 豚モモこま
A6: 豚モモこま(脂なし)
A7: 豚ひき
A8: 豚ひき(脂なし)
A9: 豚モモひき
A10: 豚モモひき(脂なし)
A11: 豚バラ
A12: 豚カタロース
A13: 豚ロース
... A53: あいびき

Sheet 備考一覧
A1: 備考一覧 | B1: 説明
A2: 角 | B2: 大きさを付けて（例 1cm角）
A3: 色紙 | B3: 大きさを付けて（例 7mm色紙）
A4: 短冊 | B4: ハム・ベーコンは書かなければ短冊
A5: 千切り
A6: g* | B6: 30g*45 このような簡易表記でOKです ＝30g×45枚（*=×の意味です）
A7: g* 開き
A8: g×
A9: g× 開き
A10: 本 | B10: ササミなどの本数発注は重量未記入でOKです
A11: 枚
A12: 枚以上 | B12: シューマイ・ギョウザ・ワンタンの皮：数量は書かずに「160枚以上」のように。袋数は当社で計算します

Sheet 使い方
A1: 使い方（3つだけ）
A2: ① はじめに「施設名記入」の所に、園の名前を入れて保存
A3: ② 注文を下へ書き足していく（納品日・品名・数量（kg）・備考）
A4: ③ 印刷して、今まで通り FAX（03-3637-8501）へ
A6: ・品名と備考は ▼ から選べます。リストに無い物も、そのまま書いてOKです
A7: ・数量は数字だけ（kg は自動で付きます）
A8: ・切り方を書かなければ、当社の規定の切り方で納品します（「切り方と商品名の一覧表」）
A9: ・g指定切りは、備考に「60g×20枚」のように
A10: ・シューマイ・ギョウザ・ワンタンの皮は、数量は空けて、備考に「160枚以上」のように
A12: 株式会社若林商店 FAX 03-3637-8501

Sheet 日付リスト
A2: =IF(ISNUMBER(注文書!$B$1),IF(MONTH(注文書!$B$1+0)=MONTH(注文書!$B$1),注文書!$B$1+0,""),TODAY()+0) -> 46311 | C2: 選択しない
A3: =IF(ISNUMBER(注文書!$B$1),IF(MONTH(注文書!$B$1+1)=MONTH(注文書!$B$1),注文書!$B$1+1,""),TODAY()+1) -> 46312 | C3: 46173.625
A4: =IF(ISNUMBER(注文書!$B$1),IF(MONTH(注文書!$B$1+2)=MONTH(注文書!$B$1),注文書!$B$1+2,""),TODAY()+2) -> 46313 | C4: 46203.625
A5: =IF(ISNUMBER(注文書!$B$1),IF(MONTH(注文書!$B$1+3)=MONTH(注文書!$B$1),注文書!$B$1+3,""),TODAY()+3) -> 46314 | C5: 46234.625
A6: =IF(ISNUMBER(注文書!$B$1),IF(MONTH(注文書!$B$1+4)=MONTH(注文書!$B$1),注文書!$B$1+4,""),TODAY()+4) -> 46315 | C6: 46265.625
A7: =IF(ISNUMBER(注文書!$B$1),IF(MONTH(注文書!$B$1+5)=MONTH(注文書!$B$1),注文書!$B$1+5,""),TODAY()+5) -> 46316 | C7: 46295.625
A8: =IF(ISNUMBER(注文書!$B$1),IF(MONTH(注文書!$B$1+6)=MONTH(注文書!$B$1),注文書!$B$1+6,""),TODAY()+6) -> 46317 | C8: 46326.625
A9: =IF(ISNUMBER(注文書!$B$1),IF(MONTH(注文書!$B$1+7)=MONTH(注文書!$B$1),注文書!$B$1+7,""),TODAY()+7) -> 46318 | C9: 46356.625
A10: =IF(ISNUMBER(注文書!$B$1),IF(MONTH(注文書!$B$1+8)=MONTH(注文書!$B$1),注文書!$B$1+8,""),TODAY()+8) -> 46319 | C10: 46387.625
A11: =IF(ISNUMBER(注文書!$B$1),IF(MONTH(注文書!$B$1+9)=MONTH(注文書!$B$1),注文書!$B$1+9,""),TODAY()+9) -> 46320 | C11: 46418.625
A12: =IF(ISNUMBER(注文書!$B$1),IF(MONTH(注文書!$B$1+10)=MONTH(注文書!$B$1),注文書!$B$1+10,""),TODAY()+10) -> 46321 | C12: 46446.625
A13: =IF(ISNUMBER(注文書!$B$1),IF(MONTH(注文書!$B$1+11)=MONTH(注文書!$B$1),注文書!$B$1+11,""),TODAY()+11) -> 46322 | C13: 46477.625
A14: =IF(ISNUMBER(注文書!$B$1),IF(MONTH(注文書!$B$1+12)=MONTH(注文書!$B$1),注文書!$B$1+12,""),TODAY()+12) -> 46323 | C14: 46507.625
A15: =IF(ISNUMBER(注文書!$B$1),IF(MONTH(注文書!$B$1+13)=MONTH(注文書!$B$1),注文書!$B$1+13,""),TODAY()+13) -> 46324 | C15: 46538.625
A16: =IF(ISNUMBER(注文書!$B$1),IF(MONTH(注文書!$B$1+14)=MONTH(注文書!$B$1),注文書!$B$1+14,""),TODAY()+14) -> 46325 | C16: 46568.625
A17: =IF(ISNUMBER(注文書!$B$1),IF(MONTH(注文書!$B$1+15)=MONTH(注文書!$B$1),注文書!$B$1+15,""),TODAY()+15) -> 46326 | C17: 46599.625
A18: =IF(ISNUMBER(注文書!$B$1),IF(MONTH(注文書!$B$1+16)=MONTH(注文書!$B$1),注文書!$B$1+16,""),TODAY()+16) -> 46327 | C18: 46630.625
A19: =IF(ISNUMBER(注文書!$B$1),IF(MONTH(注文書!$B$1+17)=MONTH(注文書!$B$1),注文書!$B$1+17,""),TODAY()+17) -> 46328 | C19: 46660.625
A20: =IF(ISNUMBER(注文書!$B$1),IF(MONTH(注文書!$B$1+18)=MONTH(注文書!$B$1),注文書!$B$1+18,""),TODAY()+18) -> 46329 | C20: 46691.625
A21: =IF(ISNUMBER(注文書!$B$1),IF(MONTH(注文書!$B$1+19)=MONTH(注文書!$B$1),注文書!$B$1+19,""),TODAY()+19) -> 46330 | C21: 46721.625
A22: =IF(ISNUMBER(注文書!$B$1),IF(MONTH(注文書!$B$1+20)=MONTH(注文書!$B$1),注文書!$B$1+20,""),TODAY()+20) -> 46331 | C22: 46752.625
A23: =IF(ISNUMBER(注文書!$B$1),IF(MONTH(注文書!$B$1+21)=MONTH(注文書!$B$1),注文書!$B$1+21,""),TODAY()+21) -> 46332
A24: =IF(ISNUMBER(注文書!$B$1),IF(MONTH(注文書!$B$1+22)=MONTH(注文書!$B$1),注文書!$B$1+22,""),TODAY()+22) -> 46333
A25: =IF(ISNUMBER(注文書!$B$1),IF(MONTH(注文書!$B$1+23)=MONTH(注文書!$B$1),注文書!$B$1+23,""),TODAY()+23) -> 46334
A26: =IF(ISNUMBER(注文書!$B$1),IF(MONTH(注文書!$B$1+24)=MONTH(注文書!$B$1),注文書!$B$1+24,""),TODAY()+24) -> 46335
A27: =IF(ISNUMBER(注文書!$B$1),IF(MONTH(注文書!$B$1+25)=MONTH(注文書!$B$1),注文書!$B$1+25,""),TODAY()+25) -> 46336
A28: =IF(ISNUMBER(注文書!$B$1),IF(MONTH(注文書!$B$1+26)=MONTH(注文書!$B$1),注文書!$B$1+26,""),TODAY()+26) -> 46337
A29: =IF(ISNUMBER(注文書!$B$1),IF(MONTH(注文書!$B$1+27)=MONTH(注文書!$B$1),注文書!$B$1+27,""),TODAY()+27) -> 46338
A30: =IF(ISNUMBER(注文書!$B$1),IF(MONTH(注文書!$B$1+28)=MONTH(注文書!$B$1),注文書!$B$1+28,""),TODAY()+28) -> 46339
A31: =IF(ISNUMBER(注文書!$B$1),IF(MONTH(注文書!$B$1+29)=MONTH(注文書!$B$1),注文書!$B$1+29,""),TODAY()+29) -> 46340
A32: =IF(ISNUMBER(注文書!$B$1),IF(MONTH(注文書!$B$1+30)=MONTH(注文書!$B$1),注文書!$B$1+30,""),TODAY()+30) -> 46341
A33: =IF(ISNUMBER(注文書!$B$1),IF(MONTH(注文書!$B$1+31)=MONTH(注文書!$B$1),注文書!$B$1+31,""),TODAY()+31) -> 46342
A34: =IF(ISNUMBER(注文書!$B$1),IF(MONTH(注文書!$B$1+32)=MONTH(注文書!$B$1),注文書!$B$1+32,""),TODAY()+32) -> 46343
A35: =IF(ISNUMBER(注文書!$B$1),IF(MONTH(注文書!$B$1+33)=MONTH(注文書!$B$1),注文書!$B$1+33,""),TODAY()+33) -> 46344
A36: =IF(ISNUMBER(注文書!$B$1),IF(MONTH(注文書!$B$1+34)=MONTH(注文書!$B$1),注文書!$B$1+34,""),TODAY()+34) -> 46345
A37: =IF(ISNUMBER(注文書!$B$1),IF(MONTH(注文書!$B$1+35)=MONTH(注文書!$B$1),注文書!$B$1+35,""),TODAY()+35) -> 46346
A38: =IF(ISNUMBER(注文書!$B$1),IF(MONTH(注文書!$B$1+36)=MONTH(注文書!$B$1),注文書!$B$1+36,""),TODAY()+36) -> 46347
A39: =IF(ISNUMBER(注文書!$B$1),IF(MONTH(注文書!$B$1+37)=MONTH(注文書!$B$1),注文書!$B$1+37,""),TODAY()+37) -> 46348
A40: =IF(ISNUMBER(注文書!$B$1),IF(MONTH(注文書!$B$1+38)=MONTH(注文書!$B$1),注文書!$B$1+38,""),TODAY()+38) -> 46349
A41: =IF(ISNUMBER(注文書!$B$1),IF(MONTH(注文書!$B$1+39)=MONTH(注文書!$B$1),注文書!$B$1+39,""),TODAY()+39) -> 46350
...
